{
 "cells": [
  {
   "cell_type": "markdown",
   "metadata": {},
   "source": [
    "# Grid search & Random Search"
   ]
  },
  {
   "cell_type": "markdown",
   "metadata": {},
   "source": [
    "تغییر خودکار تعداد نورون ها\n",
    "\n",
    "به این پارامتر ها میگیم هایپر پارامتر"
   ]
  },
  {
   "cell_type": "markdown",
   "metadata": {},
   "source": [
    "# Dataset"
   ]
  },
  {
   "cell_type": "code",
   "execution_count": 13,
   "metadata": {},
   "outputs": [],
   "source": [
    "from sklearn.datasets import make_classification\n",
    "x,y=make_classification(n_samples=1000,n_features=20,n_informative=10,n_redundant=5,n_classes=2,random_state=0)\n"
   ]
  },
  {
   "cell_type": "code",
   "execution_count": 14,
   "metadata": {},
   "outputs": [
    {
     "data": {
      "text/plain": [
       "array([ 1.45377865, -0.71918443,  2.39030279,  1.12596521, -3.47282708,\n",
       "        1.55528867, -1.48370856, -1.33406913, -2.64178634, -0.2070791 ,\n",
       "        4.89442021,  1.70620233, -1.31200569, -0.50720349, -0.18435887,\n",
       "        2.07495721, -0.98751136, -1.04461223, -0.9975594 ,  0.69396016])"
      ]
     },
     "execution_count": 14,
     "metadata": {},
     "output_type": "execute_result"
    }
   ],
   "source": [
    "x[0]"
   ]
  },
  {
   "cell_type": "code",
   "execution_count": 15,
   "metadata": {},
   "outputs": [
    {
     "data": {
      "text/plain": [
       "np.int64(0)"
      ]
     },
     "execution_count": 15,
     "metadata": {},
     "output_type": "execute_result"
    }
   ],
   "source": [
    "y[0]"
   ]
  },
  {
   "cell_type": "code",
   "execution_count": 16,
   "metadata": {},
   "outputs": [
    {
     "data": {
      "text/plain": [
       "((1000, 20), (1000,))"
      ]
     },
     "execution_count": 16,
     "metadata": {},
     "output_type": "execute_result"
    }
   ],
   "source": [
    "x.shape,y.shape"
   ]
  },
  {
   "cell_type": "code",
   "execution_count": 17,
   "metadata": {},
   "outputs": [],
   "source": [
    "from sklearn.model_selection import train_test_split\n",
    "x_train,x_test,y_train,y_test=train_test_split(x,y,test_size=0.2)"
   ]
  },
  {
   "cell_type": "code",
   "execution_count": 18,
   "metadata": {},
   "outputs": [
    {
     "data": {
      "text/plain": [
       "((800, 20), (800,))"
      ]
     },
     "execution_count": 18,
     "metadata": {},
     "output_type": "execute_result"
    }
   ],
   "source": [
    "x_train.shape,y_train.shape"
   ]
  },
  {
   "cell_type": "code",
   "execution_count": 19,
   "metadata": {},
   "outputs": [
    {
     "data": {
      "text/plain": [
       "((200, 20), (200,))"
      ]
     },
     "execution_count": 19,
     "metadata": {},
     "output_type": "execute_result"
    }
   ],
   "source": [
    "x_test.shape,y_test.shape"
   ]
  },
  {
   "cell_type": "markdown",
   "metadata": {},
   "source": [
    "# model Definition"
   ]
  },
  {
   "cell_type": "code",
   "execution_count": 20,
   "metadata": {},
   "outputs": [],
   "source": [
    "from tensorflow import keras\n",
    "import tensorflow as tf\n",
    "def create_model(hidden_units=16,optimizer='adam'):\n",
    "    model=keras.Sequential()\n",
    "    model.add(keras.layers.InputLayer(input_shape=(20,)))\n",
    "    model.add(keras.layers.Dense(units=hidden_units,activation='relu'))\n",
    "    model.add(keras.layers.Dense(units=1,activation='sigmoid'))\n",
    "    \n",
    "    model.compile(optimizer=optimizer,loss=tf.losses.binary_crossentropy,metrics=['accuracy'])\n",
    "    return model"
   ]
  },
  {
   "cell_type": "markdown",
   "metadata": {},
   "source": [
    "# Grid Search"
   ]
  },
  {
   "cell_type": "code",
   "execution_count": 21,
   "metadata": {},
   "outputs": [],
   "source": [
    "from sklearn.model_selection import GridSearchCV\n"
   ]
  },
  {
   "cell_type": "markdown",
   "metadata": {},
   "source": [
    "چون که مدل رو با تنسور فلو ساختیم و گرید سرچ با اس کا لرن نیازه که یک پل ارتباطی بین این ها داشته باشیم "
   ]
  },
  {
   "cell_type": "markdown",
   "metadata": {},
   "source": [
    "از ماژول scikeras باید استفاده کنیم با روش زیر می توانیم در حین اجرا روی برنامه نصب کنه"
   ]
  },
  {
   "cell_type": "code",
   "execution_count": 22,
   "metadata": {},
   "outputs": [
    {
     "name": "stdout",
     "output_type": "stream",
     "text": [
      "Requirement already satisfied: scikeras in d:\\code\\venvdatascience\\lib\\site-packages (0.13.0)\n",
      "Requirement already satisfied: keras>=3.2.0 in d:\\code\\venvdatascience\\lib\\site-packages (from scikeras) (3.6.0)\n",
      "Requirement already satisfied: scikit-learn>=1.4.2 in d:\\code\\venvdatascience\\lib\\site-packages (from scikeras) (1.5.1)\n",
      "Requirement already satisfied: absl-py in d:\\code\\venvdatascience\\lib\\site-packages (from keras>=3.2.0->scikeras) (2.1.0)\n",
      "Requirement already satisfied: numpy in d:\\code\\venvdatascience\\lib\\site-packages (from keras>=3.2.0->scikeras) (2.0.2)\n",
      "Requirement already satisfied: rich in d:\\code\\venvdatascience\\lib\\site-packages (from keras>=3.2.0->scikeras) (13.9.4)\n",
      "Requirement already satisfied: namex in d:\\code\\venvdatascience\\lib\\site-packages (from keras>=3.2.0->scikeras) (0.0.8)\n",
      "Requirement already satisfied: h5py in d:\\code\\venvdatascience\\lib\\site-packages (from keras>=3.2.0->scikeras) (3.12.1)\n",
      "Requirement already satisfied: optree in d:\\code\\venvdatascience\\lib\\site-packages (from keras>=3.2.0->scikeras) (0.13.0)\n",
      "Requirement already satisfied: ml-dtypes in d:\\code\\venvdatascience\\lib\\site-packages (from keras>=3.2.0->scikeras) (0.4.1)\n",
      "Requirement already satisfied: packaging in d:\\code\\venvdatascience\\lib\\site-packages (from keras>=3.2.0->scikeras) (24.1)\n",
      "Requirement already satisfied: scipy>=1.6.0 in d:\\code\\venvdatascience\\lib\\site-packages (from scikit-learn>=1.4.2->scikeras) (1.14.1)\n",
      "Requirement already satisfied: joblib>=1.2.0 in d:\\code\\venvdatascience\\lib\\site-packages (from scikit-learn>=1.4.2->scikeras) (1.4.2)\n",
      "Requirement already satisfied: typing-extensions>=4.5.0 in d:\\code\\venvdatascience\\lib\\site-packages (from optree->keras>=3.2.0->scikeras) (4.12.2)\n",
      "Requirement already satisfied: markdown-it-py>=2.2.0 in d:\\code\\venvdatascience\\lib\\site-packages (from rich->keras>=3.2.0->scikeras) (3.0.0)\n",
      "Requirement already satisfied: pygments<3.0.0,>=2.13.0 in d:\\code\\venvdatascience\\lib\\site-packages (from rich->keras>=3.2.0->scikeras) (2.18.0)\n",
      "Requirement already satisfied: mdurl~=0.1 in d:\\code\\venvdatascience\\lib\\site-packages (from markdown-it-py>=2.2.0->rich->keras>=3.2.0->scikeras) (0.1.2)\n",
      "Note: you may need to restart the kernel to use updated packages.\n"
     ]
    },
    {
     "name": "stderr",
     "output_type": "stream",
     "text": [
      "\n",
      "[notice] A new release of pip is available: 24.2 -> 24.3.1\n",
      "[notice] To update, run: python.exe -m pip install --upgrade pip\n"
     ]
    }
   ],
   "source": [
    "%pip install scikeras"
   ]
  },
  {
   "cell_type": "code",
   "execution_count": 23,
   "metadata": {},
   "outputs": [],
   "source": [
    "from scikeras.wrappers import KerasClassifier\n",
    "model=KerasClassifier(model=create_model,loss='binary_crossentropy',epochs=10,batch_size=32,verbose=0)\n"
   ]
  },
  {
   "cell_type": "markdown",
   "metadata": {},
   "source": [
    "# تعریف پارامتر "
   ]
  },
  {
   "cell_type": "markdown",
   "metadata": {},
   "source": [
    "وقتی داریم از کتابخانه scikeras  استفاده می کنیم باید قبل از نام کلید های پارامتر ها از model__ استفاده بشه\n",
    "\n",
    "بعد از اون باید آرگومان های اون تابع رو بدیم"
   ]
  },
  {
   "cell_type": "code",
   "execution_count": 24,
   "metadata": {},
   "outputs": [],
   "source": [
    "params={\n",
    "    'model__hidden_units':[16,32,64],\n",
    "    'model__optimizer':['adam','rmsprop']\n",
    "}"
   ]
  },
  {
   "cell_type": "markdown",
   "metadata": {},
   "source": [
    "استفاده از Grid search"
   ]
  },
  {
   "cell_type": "markdown",
   "metadata": {},
   "source": [
    "گرید بندی کردن داده ها"
   ]
  },
  {
   "cell_type": "code",
   "execution_count": 25,
   "metadata": {},
   "outputs": [
    {
     "name": "stderr",
     "output_type": "stream",
     "text": [
      "d:\\code\\venvdatascience\\Lib\\site-packages\\keras\\src\\layers\\core\\input_layer.py:26: UserWarning: Argument `input_shape` is deprecated. Use `shape` instead.\n",
      "  warnings.warn(\n",
      "d:\\code\\venvdatascience\\Lib\\site-packages\\keras\\src\\layers\\core\\input_layer.py:26: UserWarning: Argument `input_shape` is deprecated. Use `shape` instead.\n",
      "  warnings.warn(\n",
      "d:\\code\\venvdatascience\\Lib\\site-packages\\keras\\src\\layers\\core\\input_layer.py:26: UserWarning: Argument `input_shape` is deprecated. Use `shape` instead.\n",
      "  warnings.warn(\n",
      "d:\\code\\venvdatascience\\Lib\\site-packages\\keras\\src\\layers\\core\\input_layer.py:26: UserWarning: Argument `input_shape` is deprecated. Use `shape` instead.\n",
      "  warnings.warn(\n",
      "d:\\code\\venvdatascience\\Lib\\site-packages\\keras\\src\\layers\\core\\input_layer.py:26: UserWarning: Argument `input_shape` is deprecated. Use `shape` instead.\n",
      "  warnings.warn(\n",
      "d:\\code\\venvdatascience\\Lib\\site-packages\\keras\\src\\layers\\core\\input_layer.py:26: UserWarning: Argument `input_shape` is deprecated. Use `shape` instead.\n",
      "  warnings.warn(\n",
      "d:\\code\\venvdatascience\\Lib\\site-packages\\keras\\src\\layers\\core\\input_layer.py:26: UserWarning: Argument `input_shape` is deprecated. Use `shape` instead.\n",
      "  warnings.warn(\n",
      "d:\\code\\venvdatascience\\Lib\\site-packages\\keras\\src\\layers\\core\\input_layer.py:26: UserWarning: Argument `input_shape` is deprecated. Use `shape` instead.\n",
      "  warnings.warn(\n",
      "d:\\code\\venvdatascience\\Lib\\site-packages\\keras\\src\\layers\\core\\input_layer.py:26: UserWarning: Argument `input_shape` is deprecated. Use `shape` instead.\n",
      "  warnings.warn(\n",
      "d:\\code\\venvdatascience\\Lib\\site-packages\\keras\\src\\layers\\core\\input_layer.py:26: UserWarning: Argument `input_shape` is deprecated. Use `shape` instead.\n",
      "  warnings.warn(\n",
      "d:\\code\\venvdatascience\\Lib\\site-packages\\keras\\src\\layers\\core\\input_layer.py:26: UserWarning: Argument `input_shape` is deprecated. Use `shape` instead.\n",
      "  warnings.warn(\n",
      "d:\\code\\venvdatascience\\Lib\\site-packages\\keras\\src\\layers\\core\\input_layer.py:26: UserWarning: Argument `input_shape` is deprecated. Use `shape` instead.\n",
      "  warnings.warn(\n",
      "d:\\code\\venvdatascience\\Lib\\site-packages\\keras\\src\\layers\\core\\input_layer.py:26: UserWarning: Argument `input_shape` is deprecated. Use `shape` instead.\n",
      "  warnings.warn(\n",
      "d:\\code\\venvdatascience\\Lib\\site-packages\\keras\\src\\layers\\core\\input_layer.py:26: UserWarning: Argument `input_shape` is deprecated. Use `shape` instead.\n",
      "  warnings.warn(\n",
      "d:\\code\\venvdatascience\\Lib\\site-packages\\keras\\src\\layers\\core\\input_layer.py:26: UserWarning: Argument `input_shape` is deprecated. Use `shape` instead.\n",
      "  warnings.warn(\n",
      "d:\\code\\venvdatascience\\Lib\\site-packages\\keras\\src\\layers\\core\\input_layer.py:26: UserWarning: Argument `input_shape` is deprecated. Use `shape` instead.\n",
      "  warnings.warn(\n",
      "d:\\code\\venvdatascience\\Lib\\site-packages\\keras\\src\\layers\\core\\input_layer.py:26: UserWarning: Argument `input_shape` is deprecated. Use `shape` instead.\n",
      "  warnings.warn(\n",
      "d:\\code\\venvdatascience\\Lib\\site-packages\\keras\\src\\layers\\core\\input_layer.py:26: UserWarning: Argument `input_shape` is deprecated. Use `shape` instead.\n",
      "  warnings.warn(\n"
     ]
    },
    {
     "ename": "ValueError",
     "evalue": "\nAll the 18 fits failed.\nIt is very likely that your model is misconfigured.\nYou can try to debug the error by setting error_score='raise'.\n\nBelow are more details about the failures:\n--------------------------------------------------------------------------------\n6 fits failed with the following error:\nTraceback (most recent call last):\n  File \"d:\\code\\venvdatascience\\Lib\\site-packages\\sklearn\\model_selection\\_validation.py\", line 888, in _fit_and_score\n    estimator.fit(X_train, y_train, **fit_params)\n  File \"d:\\code\\venvdatascience\\Lib\\site-packages\\scikeras\\wrappers.py\", line 1501, in fit\n    super().fit(X=X, y=y, sample_weight=sample_weight, **kwargs)\n  File \"d:\\code\\venvdatascience\\Lib\\site-packages\\scikeras\\wrappers.py\", line 770, in fit\n    self._fit(\n  File \"d:\\code\\venvdatascience\\Lib\\site-packages\\scikeras\\wrappers.py\", line 938, in _fit\n    self._fit_keras_model(\n  File \"d:\\code\\venvdatascience\\Lib\\site-packages\\scikeras\\wrappers.py\", line 535, in _fit_keras_model\n    hist = self.model_.fit(x=X, y=y, **fit_args)\n           ^^^^^^^^^^^^^^^^^^^^^^^^^^^^^^^^^^^^^\n  File \"d:\\code\\venvdatascience\\Lib\\site-packages\\keras\\src\\utils\\traceback_utils.py\", line 122, in error_handler\n    raise e.with_traceback(filtered_tb) from None\n  File \"d:\\code\\venvdatascience\\Lib\\site-packages\\keras\\src\\backend\\tensorflow\\nn.py\", line 701, in binary_crossentropy\n    raise ValueError(\nValueError: Arguments `target` and `output` must have the same shape. Received: target.shape=(None, 1), output.shape=(None, 16)\n\n--------------------------------------------------------------------------------\n6 fits failed with the following error:\nTraceback (most recent call last):\n  File \"d:\\code\\venvdatascience\\Lib\\site-packages\\sklearn\\model_selection\\_validation.py\", line 888, in _fit_and_score\n    estimator.fit(X_train, y_train, **fit_params)\n  File \"d:\\code\\venvdatascience\\Lib\\site-packages\\scikeras\\wrappers.py\", line 1501, in fit\n    super().fit(X=X, y=y, sample_weight=sample_weight, **kwargs)\n  File \"d:\\code\\venvdatascience\\Lib\\site-packages\\scikeras\\wrappers.py\", line 770, in fit\n    self._fit(\n  File \"d:\\code\\venvdatascience\\Lib\\site-packages\\scikeras\\wrappers.py\", line 938, in _fit\n    self._fit_keras_model(\n  File \"d:\\code\\venvdatascience\\Lib\\site-packages\\scikeras\\wrappers.py\", line 535, in _fit_keras_model\n    hist = self.model_.fit(x=X, y=y, **fit_args)\n           ^^^^^^^^^^^^^^^^^^^^^^^^^^^^^^^^^^^^^\n  File \"d:\\code\\venvdatascience\\Lib\\site-packages\\keras\\src\\utils\\traceback_utils.py\", line 122, in error_handler\n    raise e.with_traceback(filtered_tb) from None\n  File \"d:\\code\\venvdatascience\\Lib\\site-packages\\keras\\src\\backend\\tensorflow\\nn.py\", line 701, in binary_crossentropy\n    raise ValueError(\nValueError: Arguments `target` and `output` must have the same shape. Received: target.shape=(None, 1), output.shape=(None, 32)\n\n--------------------------------------------------------------------------------\n6 fits failed with the following error:\nTraceback (most recent call last):\n  File \"d:\\code\\venvdatascience\\Lib\\site-packages\\sklearn\\model_selection\\_validation.py\", line 888, in _fit_and_score\n    estimator.fit(X_train, y_train, **fit_params)\n  File \"d:\\code\\venvdatascience\\Lib\\site-packages\\scikeras\\wrappers.py\", line 1501, in fit\n    super().fit(X=X, y=y, sample_weight=sample_weight, **kwargs)\n  File \"d:\\code\\venvdatascience\\Lib\\site-packages\\scikeras\\wrappers.py\", line 770, in fit\n    self._fit(\n  File \"d:\\code\\venvdatascience\\Lib\\site-packages\\scikeras\\wrappers.py\", line 938, in _fit\n    self._fit_keras_model(\n  File \"d:\\code\\venvdatascience\\Lib\\site-packages\\scikeras\\wrappers.py\", line 535, in _fit_keras_model\n    hist = self.model_.fit(x=X, y=y, **fit_args)\n           ^^^^^^^^^^^^^^^^^^^^^^^^^^^^^^^^^^^^^\n  File \"d:\\code\\venvdatascience\\Lib\\site-packages\\keras\\src\\utils\\traceback_utils.py\", line 122, in error_handler\n    raise e.with_traceback(filtered_tb) from None\n  File \"d:\\code\\venvdatascience\\Lib\\site-packages\\keras\\src\\backend\\tensorflow\\nn.py\", line 701, in binary_crossentropy\n    raise ValueError(\nValueError: Arguments `target` and `output` must have the same shape. Received: target.shape=(None, 1), output.shape=(None, 64)\n",
     "output_type": "error",
     "traceback": [
      "\u001b[1;31m---------------------------------------------------------------------------\u001b[0m",
      "\u001b[1;31mValueError\u001b[0m                                Traceback (most recent call last)",
      "Cell \u001b[1;32mIn[25], line 2\u001b[0m\n\u001b[0;32m      1\u001b[0m grid\u001b[38;5;241m=\u001b[39mGridSearchCV(estimator\u001b[38;5;241m=\u001b[39mmodel,param_grid\u001b[38;5;241m=\u001b[39mparams,cv\u001b[38;5;241m=\u001b[39m\u001b[38;5;241m3\u001b[39m)\n\u001b[1;32m----> 2\u001b[0m grid_result\u001b[38;5;241m=\u001b[39m\u001b[43mgrid\u001b[49m\u001b[38;5;241;43m.\u001b[39;49m\u001b[43mfit\u001b[49m\u001b[43m(\u001b[49m\u001b[43mx_train\u001b[49m\u001b[43m,\u001b[49m\u001b[43my_train\u001b[49m\u001b[43m)\u001b[49m\n",
      "File \u001b[1;32md:\\code\\venvdatascience\\Lib\\site-packages\\sklearn\\base.py:1473\u001b[0m, in \u001b[0;36m_fit_context.<locals>.decorator.<locals>.wrapper\u001b[1;34m(estimator, *args, **kwargs)\u001b[0m\n\u001b[0;32m   1466\u001b[0m     estimator\u001b[38;5;241m.\u001b[39m_validate_params()\n\u001b[0;32m   1468\u001b[0m \u001b[38;5;28;01mwith\u001b[39;00m config_context(\n\u001b[0;32m   1469\u001b[0m     skip_parameter_validation\u001b[38;5;241m=\u001b[39m(\n\u001b[0;32m   1470\u001b[0m         prefer_skip_nested_validation \u001b[38;5;129;01mor\u001b[39;00m global_skip_validation\n\u001b[0;32m   1471\u001b[0m     )\n\u001b[0;32m   1472\u001b[0m ):\n\u001b[1;32m-> 1473\u001b[0m     \u001b[38;5;28;01mreturn\u001b[39;00m \u001b[43mfit_method\u001b[49m\u001b[43m(\u001b[49m\u001b[43mestimator\u001b[49m\u001b[43m,\u001b[49m\u001b[43m \u001b[49m\u001b[38;5;241;43m*\u001b[39;49m\u001b[43margs\u001b[49m\u001b[43m,\u001b[49m\u001b[43m \u001b[49m\u001b[38;5;241;43m*\u001b[39;49m\u001b[38;5;241;43m*\u001b[39;49m\u001b[43mkwargs\u001b[49m\u001b[43m)\u001b[49m\n",
      "File \u001b[1;32md:\\code\\venvdatascience\\Lib\\site-packages\\sklearn\\model_selection\\_search.py:1018\u001b[0m, in \u001b[0;36mBaseSearchCV.fit\u001b[1;34m(self, X, y, **params)\u001b[0m\n\u001b[0;32m   1012\u001b[0m     results \u001b[38;5;241m=\u001b[39m \u001b[38;5;28mself\u001b[39m\u001b[38;5;241m.\u001b[39m_format_results(\n\u001b[0;32m   1013\u001b[0m         all_candidate_params, n_splits, all_out, all_more_results\n\u001b[0;32m   1014\u001b[0m     )\n\u001b[0;32m   1016\u001b[0m     \u001b[38;5;28;01mreturn\u001b[39;00m results\n\u001b[1;32m-> 1018\u001b[0m \u001b[38;5;28;43mself\u001b[39;49m\u001b[38;5;241;43m.\u001b[39;49m\u001b[43m_run_search\u001b[49m\u001b[43m(\u001b[49m\u001b[43mevaluate_candidates\u001b[49m\u001b[43m)\u001b[49m\n\u001b[0;32m   1020\u001b[0m \u001b[38;5;66;03m# multimetric is determined here because in the case of a callable\u001b[39;00m\n\u001b[0;32m   1021\u001b[0m \u001b[38;5;66;03m# self.scoring the return type is only known after calling\u001b[39;00m\n\u001b[0;32m   1022\u001b[0m first_test_score \u001b[38;5;241m=\u001b[39m all_out[\u001b[38;5;241m0\u001b[39m][\u001b[38;5;124m\"\u001b[39m\u001b[38;5;124mtest_scores\u001b[39m\u001b[38;5;124m\"\u001b[39m]\n",
      "File \u001b[1;32md:\\code\\venvdatascience\\Lib\\site-packages\\sklearn\\model_selection\\_search.py:1572\u001b[0m, in \u001b[0;36mGridSearchCV._run_search\u001b[1;34m(self, evaluate_candidates)\u001b[0m\n\u001b[0;32m   1570\u001b[0m \u001b[38;5;28;01mdef\u001b[39;00m \u001b[38;5;21m_run_search\u001b[39m(\u001b[38;5;28mself\u001b[39m, evaluate_candidates):\n\u001b[0;32m   1571\u001b[0m \u001b[38;5;250m    \u001b[39m\u001b[38;5;124;03m\"\"\"Search all candidates in param_grid\"\"\"\u001b[39;00m\n\u001b[1;32m-> 1572\u001b[0m     \u001b[43mevaluate_candidates\u001b[49m\u001b[43m(\u001b[49m\u001b[43mParameterGrid\u001b[49m\u001b[43m(\u001b[49m\u001b[38;5;28;43mself\u001b[39;49m\u001b[38;5;241;43m.\u001b[39;49m\u001b[43mparam_grid\u001b[49m\u001b[43m)\u001b[49m\u001b[43m)\u001b[49m\n",
      "File \u001b[1;32md:\\code\\venvdatascience\\Lib\\site-packages\\sklearn\\model_selection\\_search.py:995\u001b[0m, in \u001b[0;36mBaseSearchCV.fit.<locals>.evaluate_candidates\u001b[1;34m(candidate_params, cv, more_results)\u001b[0m\n\u001b[0;32m    988\u001b[0m \u001b[38;5;28;01melif\u001b[39;00m \u001b[38;5;28mlen\u001b[39m(out) \u001b[38;5;241m!=\u001b[39m n_candidates \u001b[38;5;241m*\u001b[39m n_splits:\n\u001b[0;32m    989\u001b[0m     \u001b[38;5;28;01mraise\u001b[39;00m \u001b[38;5;167;01mValueError\u001b[39;00m(\n\u001b[0;32m    990\u001b[0m         \u001b[38;5;124m\"\u001b[39m\u001b[38;5;124mcv.split and cv.get_n_splits returned \u001b[39m\u001b[38;5;124m\"\u001b[39m\n\u001b[0;32m    991\u001b[0m         \u001b[38;5;124m\"\u001b[39m\u001b[38;5;124minconsistent results. Expected \u001b[39m\u001b[38;5;132;01m{}\u001b[39;00m\u001b[38;5;124m \u001b[39m\u001b[38;5;124m\"\u001b[39m\n\u001b[0;32m    992\u001b[0m         \u001b[38;5;124m\"\u001b[39m\u001b[38;5;124msplits, got \u001b[39m\u001b[38;5;132;01m{}\u001b[39;00m\u001b[38;5;124m\"\u001b[39m\u001b[38;5;241m.\u001b[39mformat(n_splits, \u001b[38;5;28mlen\u001b[39m(out) \u001b[38;5;241m/\u001b[39m\u001b[38;5;241m/\u001b[39m n_candidates)\n\u001b[0;32m    993\u001b[0m     )\n\u001b[1;32m--> 995\u001b[0m \u001b[43m_warn_or_raise_about_fit_failures\u001b[49m\u001b[43m(\u001b[49m\u001b[43mout\u001b[49m\u001b[43m,\u001b[49m\u001b[43m \u001b[49m\u001b[38;5;28;43mself\u001b[39;49m\u001b[38;5;241;43m.\u001b[39;49m\u001b[43merror_score\u001b[49m\u001b[43m)\u001b[49m\n\u001b[0;32m    997\u001b[0m \u001b[38;5;66;03m# For callable self.scoring, the return type is only know after\u001b[39;00m\n\u001b[0;32m    998\u001b[0m \u001b[38;5;66;03m# calling. If the return type is a dictionary, the error scores\u001b[39;00m\n\u001b[0;32m    999\u001b[0m \u001b[38;5;66;03m# can now be inserted with the correct key. The type checking\u001b[39;00m\n\u001b[0;32m   1000\u001b[0m \u001b[38;5;66;03m# of out will be done in `_insert_error_scores`.\u001b[39;00m\n\u001b[0;32m   1001\u001b[0m \u001b[38;5;28;01mif\u001b[39;00m \u001b[38;5;28mcallable\u001b[39m(\u001b[38;5;28mself\u001b[39m\u001b[38;5;241m.\u001b[39mscoring):\n",
      "File \u001b[1;32md:\\code\\venvdatascience\\Lib\\site-packages\\sklearn\\model_selection\\_validation.py:529\u001b[0m, in \u001b[0;36m_warn_or_raise_about_fit_failures\u001b[1;34m(results, error_score)\u001b[0m\n\u001b[0;32m    522\u001b[0m \u001b[38;5;28;01mif\u001b[39;00m num_failed_fits \u001b[38;5;241m==\u001b[39m num_fits:\n\u001b[0;32m    523\u001b[0m     all_fits_failed_message \u001b[38;5;241m=\u001b[39m (\n\u001b[0;32m    524\u001b[0m         \u001b[38;5;124mf\u001b[39m\u001b[38;5;124m\"\u001b[39m\u001b[38;5;130;01m\\n\u001b[39;00m\u001b[38;5;124mAll the \u001b[39m\u001b[38;5;132;01m{\u001b[39;00mnum_fits\u001b[38;5;132;01m}\u001b[39;00m\u001b[38;5;124m fits failed.\u001b[39m\u001b[38;5;130;01m\\n\u001b[39;00m\u001b[38;5;124m\"\u001b[39m\n\u001b[0;32m    525\u001b[0m         \u001b[38;5;124m\"\u001b[39m\u001b[38;5;124mIt is very likely that your model is misconfigured.\u001b[39m\u001b[38;5;130;01m\\n\u001b[39;00m\u001b[38;5;124m\"\u001b[39m\n\u001b[0;32m    526\u001b[0m         \u001b[38;5;124m\"\u001b[39m\u001b[38;5;124mYou can try to debug the error by setting error_score=\u001b[39m\u001b[38;5;124m'\u001b[39m\u001b[38;5;124mraise\u001b[39m\u001b[38;5;124m'\u001b[39m\u001b[38;5;124m.\u001b[39m\u001b[38;5;130;01m\\n\u001b[39;00m\u001b[38;5;130;01m\\n\u001b[39;00m\u001b[38;5;124m\"\u001b[39m\n\u001b[0;32m    527\u001b[0m         \u001b[38;5;124mf\u001b[39m\u001b[38;5;124m\"\u001b[39m\u001b[38;5;124mBelow are more details about the failures:\u001b[39m\u001b[38;5;130;01m\\n\u001b[39;00m\u001b[38;5;132;01m{\u001b[39;00mfit_errors_summary\u001b[38;5;132;01m}\u001b[39;00m\u001b[38;5;124m\"\u001b[39m\n\u001b[0;32m    528\u001b[0m     )\n\u001b[1;32m--> 529\u001b[0m     \u001b[38;5;28;01mraise\u001b[39;00m \u001b[38;5;167;01mValueError\u001b[39;00m(all_fits_failed_message)\n\u001b[0;32m    531\u001b[0m \u001b[38;5;28;01melse\u001b[39;00m:\n\u001b[0;32m    532\u001b[0m     some_fits_failed_message \u001b[38;5;241m=\u001b[39m (\n\u001b[0;32m    533\u001b[0m         \u001b[38;5;124mf\u001b[39m\u001b[38;5;124m\"\u001b[39m\u001b[38;5;130;01m\\n\u001b[39;00m\u001b[38;5;132;01m{\u001b[39;00mnum_failed_fits\u001b[38;5;132;01m}\u001b[39;00m\u001b[38;5;124m fits failed out of a total of \u001b[39m\u001b[38;5;132;01m{\u001b[39;00mnum_fits\u001b[38;5;132;01m}\u001b[39;00m\u001b[38;5;124m.\u001b[39m\u001b[38;5;130;01m\\n\u001b[39;00m\u001b[38;5;124m\"\u001b[39m\n\u001b[0;32m    534\u001b[0m         \u001b[38;5;124m\"\u001b[39m\u001b[38;5;124mThe score on these train-test partitions for these parameters\u001b[39m\u001b[38;5;124m\"\u001b[39m\n\u001b[1;32m   (...)\u001b[0m\n\u001b[0;32m    538\u001b[0m         \u001b[38;5;124mf\u001b[39m\u001b[38;5;124m\"\u001b[39m\u001b[38;5;124mBelow are more details about the failures:\u001b[39m\u001b[38;5;130;01m\\n\u001b[39;00m\u001b[38;5;132;01m{\u001b[39;00mfit_errors_summary\u001b[38;5;132;01m}\u001b[39;00m\u001b[38;5;124m\"\u001b[39m\n\u001b[0;32m    539\u001b[0m     )\n",
      "\u001b[1;31mValueError\u001b[0m: \nAll the 18 fits failed.\nIt is very likely that your model is misconfigured.\nYou can try to debug the error by setting error_score='raise'.\n\nBelow are more details about the failures:\n--------------------------------------------------------------------------------\n6 fits failed with the following error:\nTraceback (most recent call last):\n  File \"d:\\code\\venvdatascience\\Lib\\site-packages\\sklearn\\model_selection\\_validation.py\", line 888, in _fit_and_score\n    estimator.fit(X_train, y_train, **fit_params)\n  File \"d:\\code\\venvdatascience\\Lib\\site-packages\\scikeras\\wrappers.py\", line 1501, in fit\n    super().fit(X=X, y=y, sample_weight=sample_weight, **kwargs)\n  File \"d:\\code\\venvdatascience\\Lib\\site-packages\\scikeras\\wrappers.py\", line 770, in fit\n    self._fit(\n  File \"d:\\code\\venvdatascience\\Lib\\site-packages\\scikeras\\wrappers.py\", line 938, in _fit\n    self._fit_keras_model(\n  File \"d:\\code\\venvdatascience\\Lib\\site-packages\\scikeras\\wrappers.py\", line 535, in _fit_keras_model\n    hist = self.model_.fit(x=X, y=y, **fit_args)\n           ^^^^^^^^^^^^^^^^^^^^^^^^^^^^^^^^^^^^^\n  File \"d:\\code\\venvdatascience\\Lib\\site-packages\\keras\\src\\utils\\traceback_utils.py\", line 122, in error_handler\n    raise e.with_traceback(filtered_tb) from None\n  File \"d:\\code\\venvdatascience\\Lib\\site-packages\\keras\\src\\backend\\tensorflow\\nn.py\", line 701, in binary_crossentropy\n    raise ValueError(\nValueError: Arguments `target` and `output` must have the same shape. Received: target.shape=(None, 1), output.shape=(None, 16)\n\n--------------------------------------------------------------------------------\n6 fits failed with the following error:\nTraceback (most recent call last):\n  File \"d:\\code\\venvdatascience\\Lib\\site-packages\\sklearn\\model_selection\\_validation.py\", line 888, in _fit_and_score\n    estimator.fit(X_train, y_train, **fit_params)\n  File \"d:\\code\\venvdatascience\\Lib\\site-packages\\scikeras\\wrappers.py\", line 1501, in fit\n    super().fit(X=X, y=y, sample_weight=sample_weight, **kwargs)\n  File \"d:\\code\\venvdatascience\\Lib\\site-packages\\scikeras\\wrappers.py\", line 770, in fit\n    self._fit(\n  File \"d:\\code\\venvdatascience\\Lib\\site-packages\\scikeras\\wrappers.py\", line 938, in _fit\n    self._fit_keras_model(\n  File \"d:\\code\\venvdatascience\\Lib\\site-packages\\scikeras\\wrappers.py\", line 535, in _fit_keras_model\n    hist = self.model_.fit(x=X, y=y, **fit_args)\n           ^^^^^^^^^^^^^^^^^^^^^^^^^^^^^^^^^^^^^\n  File \"d:\\code\\venvdatascience\\Lib\\site-packages\\keras\\src\\utils\\traceback_utils.py\", line 122, in error_handler\n    raise e.with_traceback(filtered_tb) from None\n  File \"d:\\code\\venvdatascience\\Lib\\site-packages\\keras\\src\\backend\\tensorflow\\nn.py\", line 701, in binary_crossentropy\n    raise ValueError(\nValueError: Arguments `target` and `output` must have the same shape. Received: target.shape=(None, 1), output.shape=(None, 32)\n\n--------------------------------------------------------------------------------\n6 fits failed with the following error:\nTraceback (most recent call last):\n  File \"d:\\code\\venvdatascience\\Lib\\site-packages\\sklearn\\model_selection\\_validation.py\", line 888, in _fit_and_score\n    estimator.fit(X_train, y_train, **fit_params)\n  File \"d:\\code\\venvdatascience\\Lib\\site-packages\\scikeras\\wrappers.py\", line 1501, in fit\n    super().fit(X=X, y=y, sample_weight=sample_weight, **kwargs)\n  File \"d:\\code\\venvdatascience\\Lib\\site-packages\\scikeras\\wrappers.py\", line 770, in fit\n    self._fit(\n  File \"d:\\code\\venvdatascience\\Lib\\site-packages\\scikeras\\wrappers.py\", line 938, in _fit\n    self._fit_keras_model(\n  File \"d:\\code\\venvdatascience\\Lib\\site-packages\\scikeras\\wrappers.py\", line 535, in _fit_keras_model\n    hist = self.model_.fit(x=X, y=y, **fit_args)\n           ^^^^^^^^^^^^^^^^^^^^^^^^^^^^^^^^^^^^^\n  File \"d:\\code\\venvdatascience\\Lib\\site-packages\\keras\\src\\utils\\traceback_utils.py\", line 122, in error_handler\n    raise e.with_traceback(filtered_tb) from None\n  File \"d:\\code\\venvdatascience\\Lib\\site-packages\\keras\\src\\backend\\tensorflow\\nn.py\", line 701, in binary_crossentropy\n    raise ValueError(\nValueError: Arguments `target` and `output` must have the same shape. Received: target.shape=(None, 1), output.shape=(None, 64)\n"
     ]
    }
   ],
   "source": [
    "grid=GridSearchCV(estimator=model,param_grid=params,cv=3)\n",
    "grid_result=grid.fit(x_train,y_train)"
   ]
  }
 ],
 "metadata": {
  "kernelspec": {
   "display_name": "venvdatascience",
   "language": "python",
   "name": "python3"
  },
  "language_info": {
   "codemirror_mode": {
    "name": "ipython",
    "version": 3
   },
   "file_extension": ".py",
   "mimetype": "text/x-python",
   "name": "python",
   "nbconvert_exporter": "python",
   "pygments_lexer": "ipython3",
   "version": "3.12.3"
  }
 },
 "nbformat": 4,
 "nbformat_minor": 2
}
